Workbook

Sheet dashboard
A2: OPEN UNPAID ORDERS | F2: Total outstanding | H2: =SUM(H5:H7) -> 2800 | L2: OVERDUE TASKS | O2: Total Tasks | Q2: =COUNTA(N5:N7) -> 3
A4: Order Number | B4: Status | C4: Order Date | D4: First Name | E4: Last Name | F4: Item | G4: Unit Cost | H4: Sale Price | L4: Category | M4: Importance | N4: Task | O4: Due Date | P4: Est Total Hours | Q4: % Completed
A5: =IFERROR(__xludf.DUMMYFUNCTION("FILTER(Orders!A2:H1001,Orders!B2:B1001=""open"", Orders!I2:I1001="""")"),1041.0) -> 1041 | B5: =IFERROR(__xludf.DUMMYFUNCTION("""COMPUTED_VALUE"""),"Open") -> Open | C5: =IFERROR(__xludf.DUMMYFUNCTION("""COMPUTED_VALUE"""),46138.0) -> 46138 | D5: =IFERROR(__xludf.DUMMYFUNCTION("""COMPUTED_VALUE"""),"Jena") -> Jena | E5: =IFERROR(__xludf.DUMMYFUNCTION("""COMPUTED_VALUE"""),"Barker") -> Barker | F5: =IFERROR(__xludf.DUMMYFUNCTION("""COMPUTED_VALUE"""),"Dining table") -> Dining table | G5: =IFERROR(__xludf.DUMMYFUNCTION("""COMPUTED_VALUE"""),500.0) -> 500 | H5: =IFERROR(__xludf.DUMMYFUNCTION("""COMPUTED_VALUE"""),1200.0) -> 1200 | L5: =IFERROR(__xludf.DUMMYFUNCTION("FILTER(Tasks!A2:H1001, Tasks!D2:D1001<TODAY(), Tasks!G2:G1001<100,Tasks!A2:A1001<>"""")"),"Fabrication") -> Fabrication | M5: =IFERROR(__xludf.DUMMYFUNCTION("""COMPUTED_VALUE"""),"Low") -> Low | N5: =IFERROR(__xludf.DUMMYFUNCTION("""COMPUTED_VALUE"""),"Build storage for tools") -> Build storage for tools | O5: =IFERROR(__xludf.DUMMYFUNCTION("""COMPUTED_VALUE"""),46145.0) -> 46145 | P5: =IFERROR(__xludf.DUMMYFUNCTION("""COMPUTED_VALUE"""),2.0) -> 2 | Q5: =IFERROR(__xludf.DUMMYFUNCTION("""COMPUTED_VALUE"""),1.5) -> 1.5 | R5: =IFERROR(__xludf.DUMMYFUNCTION("""COMPUTED_VALUE"""),0.75) -> 0.75 | S5: =IFERROR(__xludf.DUMMYFUNCTION("""COMPUTED_VALUE"""),"")
A6: =IFERROR(__xludf.DUMMYFUNCTION("""COMPUTED_VALUE"""),1043.0) -> 1043 | B6: =IFERROR(__xludf.DUMMYFUNCTION("""COMPUTED_VALUE"""),"Open") -> Open | C6: =IFERROR(__xludf.DUMMYFUNCTION("""COMPUTED_VALUE"""),46141.0) -> 46141 | D6: =IFERROR(__xludf.DUMMYFUNCTION("""COMPUTED_VALUE"""),"Clifford") -> Clifford | E6: =IFERROR(__xludf.DUMMYFUNCTION("""COMPUTED_VALUE"""),"Woodward") -> Woodward | F6: =IFERROR(__xludf.DUMMYFUNCTION("""COMPUTED_VALUE"""),"Dining table") -> Dining table | G6: =IFERROR(__xludf.DUMMYFUNCTION("""COMPUTED_VALUE"""),500.0) -> 500 | H6: =IFERROR(__xludf.DUMMYFUNCTION("""COMPUTED_VALUE"""),1200.0) -> 1200 | L6: =IFERROR(__xludf.DUMMYFUNCTION("""COMPUTED_VALUE"""),"Shop maintenance") -> Shop maintenance | M6: =IFERROR(__xludf.DUMMYFUNCTION("""COMPUTED_VALUE"""),"Med") -> Med | N6: =IFERROR(__xludf.DUMMYFUNCTION("""COMPUTED_VALUE"""),"Deep clean of dust collector") -> Deep clean of dust collector | O6: =IFERROR(__xludf.DUMMYFUNCTION("""COMPUTED_VALUE"""),46126.0) -> 46126 | P6: =IFERROR(__xludf.DUMMYFUNCTION("""COMPUTED_VALUE"""),2.0) -> 2 | Q6: =IFERROR(__xludf.DUMMYFUNCTION("""COMPUTED_VALUE"""),2.0) -> 2 | R6: =IFERROR(__xludf.DUMMYFUNCTION("""COMPUTED_VALUE"""),0.1) -> 0.1 | S6: =IFERROR(__xludf.DUMMYFUNCTION("""COMPUTED_VALUE"""),"")
A7: =IFERROR(__xludf.DUMMYFUNCTION("""COMPUTED_VALUE"""),1053.0) -> 1053 | B7: =IFERROR(__xludf.DUMMYFUNCTION("""COMPUTED_VALUE"""),"Open") -> Open | C7: =IFERROR(__xludf.DUMMYFUNCTION("""COMPUTED_VALUE"""),46147.0) -> 46147 | D7: =IFERROR(__xludf.DUMMYFUNCTION("""COMPUTED_VALUE"""),"Krisha") -> Krisha | E7: =IFERROR(__xludf.DUMMYFUNCTION("""COMPUTED_VALUE"""),"Fuentes") -> Fuentes | F7: =IFERROR(__xludf.DUMMYFUNCTION("""COMPUTED_VALUE"""),"End Table") -> End Table | G7: =IFERROR(__xludf.DUMMYFUNCTION("""COMPUTED_VALUE"""),180.0) -> 180 | H7: =IFERROR(__xludf.DUMMYFUNCTION("""COMPUTED_VALUE"""),400.0) -> 400 | L7: =IFERROR(__xludf.DUMMYFUNCTION("""COMPUTED_VALUE"""),"Shop maintenance") -> Shop maintenance | M7: =IFERROR(__xludf.DUMMYFUNCTION("""COMPUTED_VALUE"""),"Med") -> Med | N7: =IFERROR(__xludf.DUMMYFUNCTION("""COMPUTED_VALUE"""),"Replace blades on jointer") -> Replace blades on jointer | O7: =IFERROR(__xludf.DUMMYFUNCTION("""COMPUTED_VALUE"""),46132.0) -> 46132 | P7: =IFERROR(__xludf.DUMMYFUNCTION("""COMPUTED_VALUE"""),1.0) -> 1 | Q7: =IFERROR(__xludf.DUMMYFUNCTION("""COMPUTED_VALUE"""),1.0) -> 1 | R7: =IFERROR(__xludf.DUMMYFUNCTION("""COMPUTED_VALUE"""),0.1) -> 0.1 | S7: =IFERROR(__xludf.DUMMYFUNCTION("""COMPUTED_VALUE"""),"")
L8: =IFERROR(__xludf.DUMMYFUNCTION("""COMPUTED_VALUE"""),"Materials") -> Materials | M8: =IFERROR(__xludf.DUMMYFUNCTION("""COMPUTED_VALUE"""),"Med") -> Med | N8: =IFERROR(__xludf.DUMMYFUNCTION("""COMPUTED_VALUE"""),"Source walnut for Country House project") -> Source walnut for Country House project | O8: =IFERROR(__xludf.DUMMYFUNCTION("""COMPUTED_VALUE"""),46145.0) -> 46145 | P8: =IFERROR(__xludf.DUMMYFUNCTION("""COMPUTED_VALUE"""),2.0) -> 2 | Q8: =IFERROR(__xludf.DUMMYFUNCTION("""COMPUTED_VALUE"""),0.5) -> 0.5 | R8: =IFERROR(__xludf.DUMMYFUNCTION("""COMPUTED_VALUE"""),0.2) -> 0.2 | S8: =IFERROR(__xludf.DUMMYFUNCTION("""COMPUTED_VALUE"""),"")
L9: =IFERROR(__xludf.DUMMYFUNCTION("""COMPUTED_VALUE"""),"Shop maintenance") -> Shop maintenance | M9: =IFERROR(__xludf.DUMMYFUNCTION("""COMPUTED_VALUE"""),"Med") -> Med | N9: =IFERROR(__xludf.DUMMYFUNCTION("""COMPUTED_VALUE"""),"Deep clean of dust collector") -> Deep clean of dust collector | O9: =IFERROR(__xludf.DUMMYFUNCTION("""COMPUTED_VALUE"""),46136.0) -> 46136 | P9: =IFERROR(__xludf.DUMMYFUNCTION("""COMPUTED_VALUE"""),2.0) -> 2 | Q9: =IFERROR(__xludf.DUMMYFUNCTION("""COMPUTED_VALUE"""),2.0) -> 2 | R9: =IFERROR(__xludf.DUMMYFUNCTION("""COMPUTED_VALUE"""),0.1) -> 0.1 | S9: =IFERROR(__xludf.DUMMYFUNCTION("""COMPUTED_VALUE"""),"")
L10: =IFERROR(__xludf.DUMMYFUNCTION("""COMPUTED_VALUE"""),"Shop maintenance") -> Shop maintenance | M10: =IFERROR(__xludf.DUMMYFUNCTION("""COMPUTED_VALUE"""),"Med") -> Med | N10: =IFERROR(__xludf.DUMMYFUNCTION("""COMPUTED_VALUE"""),"Fix tablesaw") -> Fix tablesaw | O10: =IFERROR(__xludf.DUMMYFUNCTION("""COMPUTED_VALUE"""),46140.0) -> 46140 | P10: =IFERROR(__xludf.DUMMYFUNCTION("""COMPUTED_VALUE"""),1.0) -> 1 | Q10: =IFERROR(__xludf.DUMMYFUNCTION("""COMPUTED_VALUE"""),1.0) -> 1 | R10: =IFERROR(__xludf.DUMMYFUNCTION("""COMPUTED_VALUE"""),0.1) -> 0.1 | S10: =IFERROR(__xludf.DUMMYFUNCTION("""COMPUTED_VALUE"""),"")
L11: =IFERROR(__xludf.DUMMYFUNCTION("""COMPUTED_VALUE"""),"Fabrication") -> Fabrication | M11: =IFERROR(__xludf.DUMMYFUNCTION("""COMPUTED_VALUE"""),"Med") -> Med | N11: =IFERROR(__xludf.DUMMYFUNCTION("""COMPUTED_VALUE"""),"Apply finish to custom benches") -> Apply finish to custom benches | O11: =IFERROR(__xludf.DUMMYFUNCTION("""COMPUTED_VALUE"""),46144.0) -> 46144 | P11: =IFERROR(__xludf.DUMMYFUNCTION("""COMPUTED_VALUE"""),2.0) -> 2 | Q11: =IFERROR(__xludf.DUMMYFUNCTION("""COMPUTED_VALUE"""),0.0) -> 0 | R11: =IFERROR(__xludf.DUMMYFUNCTION("""COMPUTED_VALUE"""),0.0) -> 0 | S11: =IFERROR(__xludf.DUMMYFUNCTION("""COMPUTED_VALUE"""),"")
L12: =IFERROR(__xludf.DUMMYFUNCTION("""COMPUTED_VALUE"""),"Shop maintenance") -> Shop maintenance | M12: =IFERROR(__xludf.DUMMYFUNCTION("""COMPUTED_VALUE"""),"Med") -> Med | N12: =IFERROR(__xludf.DUMMYFUNCTION("""COMPUTED_VALUE"""),"Deep clean of dust collector") -> Deep clean of dust collector | O12: =IFERROR(__xludf.DUMMYFUNCTION("""COMPUTED_VALUE"""),46143.0) -> 46143 | P12: =IFERROR(__xludf.DUMMYFUNCTION("""COMPUTED_VALUE"""),2.0) -> 2 | Q12: =IFERROR(__xludf.DUMMYFUNCTION("""COMPUTED_VALUE"""),2.0) -> 2 | R12: =IFERROR(__xludf.DUMMYFUNCTION("""COMPUTED_VALUE"""),0.1) -> 0.1 | S12: =IFERROR(__xludf.DUMMYFUNCTION("""COMPUTED_VALUE"""),"")
A20: ORDERS PAID PENDING DELIVERY | L20: HIGH PRIORITY TASKS | O20: Total Tasks | Q20: =COUNTA(N23:N32) -> 10
A21: Order Number | B21: Status | C21: Order Date | D21: First Name | E21: Last Name | F21: Item | G21: Unit Cost | H21: Sale Price
A22: =IFERROR(__xludf.DUMMYFUNCTION("sort(FILTER(Orders!A2:H1001,Orders!B2:B1001=""open"", Orders!I2:I1001=""Y"", Orders!J2:J1001=""Y""), 3,""true"")"),1001.0) -> 1001 | B22: =IFERROR(__xludf.DUMMYFUNCTION("""COMPUTED_VALUE"""),"Open") -> Open | C22: =IFERROR(__xludf.DUMMYFUNCTION("""COMPUTED_VALUE"""),46087.0) -> 46087 | D22: =IFERROR(__xludf.DUMMYFUNCTION("""COMPUTED_VALUE"""),"Francesco") -> Francesco | E22: =IFERROR(__xludf.DUMMYFUNCTION("""COMPUTED_VALUE"""),"Oconnor") -> Oconnor | F22: =IFERROR(__xludf.DUMMYFUNCTION("""COMPUTED_VALUE"""),"Bed Frame") -> Bed Frame | G22: =IFERROR(__xludf.DUMMYFUNCTION("""COMPUTED_VALUE"""),350.0) -> 350 | H22: =IFERROR(__xludf.DUMMYFUNCTION("""COMPUTED_VALUE"""),800.0) -> 800 | L22: Category | M22: Importance | N22: Task | O22: Due Date | P22: Est Total Hours | Q22: % Completed | R22: Big Projet
A23: =IFERROR(__xludf.DUMMYFUNCTION("""COMPUTED_VALUE"""),1003.0) -> 1003 | B23: =IFERROR(__xludf.DUMMYFUNCTION("""COMPUTED_VALUE"""),"Open") -> Open | C23: =IFERROR(__xludf.DUMMYFUNCTION("""COMPUTED_VALUE"""),46088.0) -> 46088 | D23: =IFERROR(__xludf.DUMMYFUNCTION("""COMPUTED_VALUE"""),"Lochlan") -> Lochlan | E23: =IFERROR(__xludf.DUMMYFUNCTION("""COMPUTED_VALUE"""),"Frank") -> Frank | F23: =IFERROR(__xludf.DUMMYFUNCTION("""COMPUTED_VALUE"""),"Bed Frame") -> Bed Frame | G23: =IFERROR(__xludf.DUMMYFUNCTION("""COMPUTED_VALUE"""),350.0) -> 350 | H23: =IFERROR(__xludf.DUMMYFUNCTION("""COMPUTED_VALUE"""),800.0) -> 800 | L23: =IFERROR(__xludf.DUMMYFUNCTION("SORT(FILTER(Tasks!A2:H1001, Tasks!B2:B1001=""HIGH"",Tasks!G2:G1001<100),4,TRUE)"),"Materials") -> Materials | M23: =IFERROR(__xludf.DUMMYFUNCTION("""COMPUTED_VALUE"""),"High") -> High | N23: =IFERROR(__xludf.DUMMYFUNCTION("""COMPUTED_VALUE"""),"Source marble for tabletop") -> Source marble for tabletop | O23: =IFERROR(__xludf.DUMMYFUNCTION("""COMPUTED_VALUE"""),46148.0) -> 46148 | P23: =IFERROR(__xludf.DUMMYFUNCTION("""COMPUTED_VALUE"""),2.0) -> 2 | Q23: =IFERROR(__xludf.DUMMYFUNCTION("""COMPUTED_VALUE"""),0.0) -> 0 | R23: =IFERROR(__xludf.DUMMYFUNCTION("""COMPUTED_VALUE"""),0.0) -> 0 | S23: =IFERROR(__xludf.DUMMYFUNCTION("""COMPUTED_VALUE"""),"")
A24: =IFERROR(__xludf.DUMMYFUNCTION("""COMPUTED_VALUE"""),1020.0) -> 1020 | B24: =IFERROR(__xludf.DUMMYFUNCTION("""COMPUTED_VALUE"""),"Open") -> Open | C24: =IFERROR(__xludf.DUMMYFUNCTION("""COMPUTED_VALUE"""),46113.0) -> 46113 | D24: =IFERROR(__xludf.DUMMYFUNCTION("""COMPUTED_VALUE"""),"Zakir") -> Zakir | E24: =IFERROR(__xludf.DUMMYFUNCTION("""COMPUTED_VALUE"""),"Roberson") -> Roberson | F24: =IFERROR(__xludf.DUMMYFUNCTION("""COMPUTED_VALUE"""),"Dining table") -> Dining table | G24: =IFERROR(__xludf.DUMMYFUNCTION("""COMPUTED_VALUE"""),500.0) -> 500 | H24: =IFERROR(__xludf.DUMMYFUNCTION("""COMPUTED_VALUE"""),1200.0) -> 1200 | L24: =IFERROR(__xludf.DUMMYFUNCTION("""COMPUTED_VALUE"""),"Installation") -> Installation | M24: =IFERROR(__xludf.DUMMYFUNCTION("""COMPUTED_VALUE"""),"High") -> High | N24: =IFERROR(__xludf.DUMMYFUNCTION("""COMPUTED_VALUE"""),"Install custom bookshelves in Country House project") -> Install custom bookshelves in Country House project | O24: =IFERROR(__xludf.DUMMYFUNCTION("""COMPUTED_VALUE"""),46151.0) -> 46151 | P24: =IFERROR(__xludf.DUMMYFUNCTION("""COMPUTED_VALUE"""),6.0) -> 6 | Q24: =IFERROR(__xludf.DUMMYFUNCTION("""COMPUTED_VALUE"""),0.5) -> 0.5 | R24: =IFERROR(__xludf.DUMMYFUNCTION("""COMPUTED_VALUE"""),0.1) -> 0.1 | S24: =IFERROR(__xludf.DUMMYFUNCTION("""COMPUTED_VALUE"""),"")
A25: =IFERROR(__xludf.DUMMYFUNCTION("""COMPUTED_VALUE"""),1027.0) -> 1027 | B25: =IFERROR(__xludf.DUMMYFUNCTION("""COMPUTED_VALUE"""),"Open") -> Open | C25: =IFERROR(__xludf.DUMMYFUNCTION("""COMPUTED_VALUE"""),46120.0) -> 46120 | D25: =IFERROR(__xludf.DUMMYFUNCTION("""COMPUTED_VALUE"""),"Rayhan") -> Rayhan | E25: =IFERROR(__xludf.DUMMYFUNCTION("""COMPUTED_VALUE"""),"Kennedy") -> Kennedy | F25: =IFERROR(__xludf.DUMMYFUNCTION("""COMPUTED_VALUE"""),"Dining table") -> Dining table | G25: =IFERROR(__xludf.DUMMYFUNCTION("""COMPUTED_VALUE"""),500.0) -> 500 | H25: =IFERROR(__xludf.DUMMYFUNCTION("""COMPUTED_VALUE"""),1200.0) -> 1200 | L25: =IFERROR(__xludf.DUMMYFUNCTION("""COMPUTED_VALUE"""),"Fabrication") -> Fabrication | M25: =IFERROR(__xludf.DUMMYFUNCTION("""COMPUTED_VALUE"""),"High") -> High | N25: =IFERROR(__xludf.DUMMYFUNCTION("""COMPUTED_VALUE"""),"Glue large tabletop") -> Glue large tabletop | O25: =IFERROR(__xludf.DUMMYFUNCTION("""COMPUTED_VALUE"""),46153.0) -> 46153 | P25: =IFERROR(__xludf.DUMMYFUNCTION("""COMPUTED_VALUE"""),4.0) -> 4 | Q25: =IFERROR(__xludf.DUMMYFUNCTION("""COMPUTED_VALUE"""),0.0) -> 0 | R25: =IFERROR(__xludf.DUMMYFUNCTION("""COMPUTED_VALUE"""),0.0) -> 0 | S25: =IFERROR(__xludf.DUMMYFUNCTION("""COMPUTED_VALUE"""),"")
A26: =IFERROR(__xludf.DUMMYFUNCTION("""COMPUTED_VALUE"""),1029.0) -> 1029 | B26: =IFERROR(__xludf.DUMMYFUNCTION("""COMPUTED_VALUE"""),"Open") -> Open | C26: =IFERROR(__xludf.DUMMYFUNCTION("""COMPUTED_VALUE"""),46123.0) -> 46123 | D26: =IFERROR(__xludf.DUMMYFUNCTION("""COMPUTED_VALUE"""),"Larissa") -> Larissa | E26: =IFERROR(__xludf.DUMMYFUNCTION("""COMPUTED_VALUE"""),"Gough") -> Gough | F26: =IFERROR(__xludf.DUMMYFUNCTION("""COMPUTED_VALUE"""),"Dining table") -> Dining table | G26: =IFERROR(__xludf.DUMMYFUNCTION("""COMPUTED_VALUE"""),500.0) -> 500 | H26: =IFERROR(__xludf.DUMMYFUNCTION("""COMPUTED_VALUE"""),1200.0) -> 1200 | L26: =IFERROR(__xludf.DUMMYFUNCTION("""COMPUTED_VALUE"""),"Fabrication") -> Fabrication | M26: =IFERROR(__xludf.DUMMYFUNCTION("""COMPUTED_VALUE"""),"High") -> High | N26: =IFERROR(__xludf.DUMMYFUNCTION("""COMPUTED_VALUE"""),"Table assembly") -> Table assembly | O26: =IFERROR(__xludf.DUMMYFUNCTION("""COMPUTED_VALUE"""),46154.0) -> 46154 | P26: =IFERROR(__xludf.DUMMYFUNCTION("""COMPUTED_VALUE"""),6.0) -> 6 | Q26: =IFERROR(__xludf.DUMMYFUNCTION("""COMPUTED_VALUE"""),0.0) -> 0 | R26: =IFERROR(__xludf.DUMMYFUNCTION("""COMPUTED_VALUE"""),0.0) -> 0 | S26: =IFERROR(__xludf.DUMMYFUNCTION("""COMPUTED_VALUE"""),"")
A27: =IFERROR(__xludf.DUMMYFUNCTION("""COMPUTED_VALUE"""),1030.0) -> 1030 | B27: =IFERROR(__xludf.DUMMYFUNCTION("""COMPUTED_VALUE"""),"Open") -> Open | C27: =IFERROR(__xludf.DUMMYFUNCTION("""COMPUTED_VALUE"""),46123.0) -> 46123 | D27: =IFERROR(__xludf.DUMMYFUNCTION("""COMPUTED_VALUE"""),"Dalia") -> Dalia | E27: =IFERROR(__xludf.DUMMYFUNCTION("""COMPUTED_VALUE"""),"Merritt") -> Merritt | F27: =IFERROR(__xludf.DUMMYFUNCTION("""COMPUTED_VALUE"""),"Large Desk") -> Large Desk | G27: =IFERROR(__xludf.DUMMYFUNCTION("""COMPUTED_VALUE"""),300.0) -> 300 | H27: =IFERROR(__xludf.DUMMYFUNCTION("""COMPUTED_VALUE"""),600.0) -> 600 | L27: =IFERROR(__xludf.DUMMYFUNCTION("""COMPUTED_VALUE"""),"Installation") -> Installation | M27: =IFERROR(__xludf.DUMMYFUNCTION("""COMPUTED_VALUE"""),"High") -> High | N27: =IFERROR(__xludf.DUMMYFUNCTION("""COMPUTED_VALUE"""),"Install custom kitchen cabinets in Country House project") -> Install custom kitchen cabinets in Country House project | O27: =IFERROR(__xludf.DUMMYFUNCTION("""COMPUTED_VALUE"""),46156.0) -> 46156 | P27: =IFERROR(__xludf.DUMMYFUNCTION("""COMPUTED_VALUE"""),8.0) -> 8 | Q27: =IFERROR(__xludf.DUMMYFUNCTION("""COMPUTED_VALUE"""),1.0) -> 1 | R27: =IFERROR(__xludf.DUMMYFUNCTION("""COMPUTED_VALUE"""),0.1) -> 0.1 | S27: =IFERROR(__xludf.DUMMYFUNCTION("""COMPUTED_VALUE"""),"")
A28: =IFERROR(__xludf.DUMMYFUNCTION("""COMPUTED_VALUE"""),1035.0) -> 1035 | B28: =IFERROR(__xludf.DUMMYFUNCTION("""COMPUTED_VALUE"""),"Open") -> Open | C28: =IFERROR(__xludf.DUMMYFUNCTION("""COMPUTED_VALUE"""),46128.0) -> 46128 | D28: =IFERROR(__xludf.DUMMYFUNCTION("""COMPUTED_VALUE"""),"Saima") -> Saima | E28: =IFERROR(__xludf.DUMMYFUNCTION("""COMPUTED_VALUE"""),"Griffin") -> Griffin | F28: =IFERROR(__xludf.DUMMYFUNCTION("""COMPUTED_VALUE"""),"Large Desk") -> Large Desk | G28: =IFERROR(__xludf.DUMMYFUNCTION("""COMPUTED_VALUE"""),300.0) -> 300 | H28: =IFERROR(__xludf.DUMMYFUNCTION("""COMPUTED_VALUE"""),600.0) -> 600 | L28: =IFERROR(__xludf.DUMMYFUNCTION("""COMPUTED_VALUE"""),"Fabrication") -> Fabrication | M28: =IFERROR(__xludf.DUMMYFUNCTION("""COMPUTED_VALUE"""),"High") -> High | N28: =IFERROR(__xludf.DUMMYFUNCTION("""COMPUTED_VALUE"""),"Apply the finish to the table") -> Apply the finish to the table | O28: =IFERROR(__xludf.DUMMYFUNCTION("""COMPUTED_VALUE"""),46156.0) -> 46156 | P28: =IFERROR(__xludf.DUMMYFUNCTION("""COMPUTED_VALUE"""),6.0) -> 6 | Q28: =IFERROR(__xludf.DUMMYFUNCTION("""COMPUTED_VALUE"""),0.0) -> 0 | R28: =IFERROR(__xludf.DUMMYFUNCTION("""COMPUTED_VALUE"""),0.0) -> 0 | S28: =IFERROR(__xludf.DUMMYFUNCTION("""COMPUTED_VALUE"""),"")
A29: =IFERROR(__xludf.DUMMYFUNCTION("""COMPUTED_VALUE"""),1047.0) -> 1047 | B29: =IFERROR(__xludf.DUMMYFUNCTION("""COMPUTED_VALUE"""),"Open") -> Open | C29: =IFERROR(__xludf.DUMMYFUNCTION("""COMPUTED_VALUE"""),46143.0) -> 46143 | D29: =IFERROR(__xludf.DUMMYFUNCTION("""COMPUTED_VALUE"""),"Alistair") -> Alistair | E29: =IFERROR(__xludf.DUMMYFUNCTION("""COMPUTED_VALUE"""),"Nunez") -> Nunez | F29: =IFERROR(__xludf.DUMMYFUNCTION("""COMPUTED_VALUE"""),"Small Desk") -> Small Desk | G29: =IFERROR(__xludf.DUMMYFUNCTION("""COMPUTED_VALUE"""),200.0) -> 200 | H29: =IFERROR(__xludf.DUMMYFUNCTION("""COMPUTED_VALUE"""),400.0) -> 400 | L29: =IFERROR(__xludf.DUMMYFUNCTION("""COMPUTED_VALUE"""),"Design") -> Design | M29: =IFERROR(__xludf.DUMMYFUNCTION("""COMPUTED_VALUE"""),"High") -> High | N29: =IFERROR(__xludf.DUMMYFUNCTION("""COMPUTED_VALUE"""),"Prepare custom drawings for staircase for Country House project") -> Prepare custom drawings for staircase for Country House project | O29: =IFERROR(__xludf.DUMMYFUNCTION("""COMPUTED_VALUE"""),46161.0) -> 46161 | P29: =IFERROR(__xludf.DUMMYFUNCTION("""COMPUTED_VALUE"""),16.0) -> 16 | Q29: =IFERROR(__xludf.DUMMYFUNCTION("""COMPUTED_VALUE"""),3.0) -> 3 | R29: =IFERROR(__xludf.DUMMYFUNCTION("""COMPUTED_VALUE"""),0.2) -> 0.2 | S29: =IFERROR(__xludf.DUMMYFUNCTION("""COMPUTED_VALUE"""),"Y") -> Y
L30: =IFERROR(__xludf.DUMMYFUNCTION("""COMPUTED_VALUE"""),"Design") -> Design | M30: =IFERROR(__xludf.DUMMYFUNCTION("""COMPUTED_VALUE"""),"High") -> High | N30: =IFERROR(__xludf.DUMMYFUNCTION("""COMPUTED_VALUE"""),"Design bunk beds for the kids' room in Country House project") -> Design bunk beds for the kids' room in Country House project | O30: =IFERROR(__xludf.DUMMYFUNCTION("""COMPUTED_VALUE"""),46165.0) -> 46165 | P30: =IFERROR(__xludf.DUMMYFUNCTION("""COMPUTED_VALUE"""),12.0) -> 12 | Q30: =IFERROR(__xludf.DUMMYFUNCTION("""COMPUTED_VALUE"""),1.5) -> 1.5 | R30: =IFERROR(__xludf.DUMMYFUNCTION("""COMPUTED_VALUE"""),0.1) -> 0.1 | S30: =IFERROR(__xludf.DUMMYFUNCTION("""COMPUTED_VALUE"""),"Y") -> Y
L31: =IFERROR(__xludf.DUMMYFUNCTION("""COMPUTED_VALUE"""),"Design") -> Design | M31: =IFERROR(__xludf.DUMMYFUNCTION("""COMPUTED_VALUE"""),"High") -> High | N31: =IFERROR(__xludf.DUMMYFUNCTION("""COMPUTED_VALUE"""),"Prepare front door & entry way drawings for Country House project") -> Prepare front door & entry way drawings for Country House project | O31: =IFERROR(__xludf.DUMMYFUNCTION("""COMPUTED_VALUE"""),46168.0) -> 46168 | P31: =IFERROR(__xludf.DUMMYFUNCTION("""COMPUTED_VALUE"""),12.0) -> 12 | Q31: =IFERROR(__xludf.DUMMYFUNCTION("""COMPUTED_VALUE"""),0.0) -> 0 | R31: =IFERROR(__xludf.DUMMYFUNCTION("""COMPUTED_VALUE"""),0.0) -> 0 | S31: =IFERROR(__xludf.DUMMYFUNCTION("""COMPUTED_VALUE"""),"Y") -> Y
L32: =IFERROR(__xludf.DUMMYFUNCTION("""COMPUTED_VALUE"""),"Design") -> Design | M32: =IFERROR(__xludf.DUMMYFUNCTION("""COMPUTED_VALUE"""),"High") -> High | N32: =IFERROR(__xludf.DUMMYFUNCTION("""COMPUTED_VALUE"""),"Prepare entertainment center drawings for Country House project") -> Prepare entertainment center drawings for Country House project | O32: =IFERROR(__xludf.DUMMYFUNCTION("""COMPUTED_VALUE"""),46168.0) -> 46168 | P32: =IFERROR(__xludf.DUMMYFUNCTION("""COMPUTED_VALUE"""),12.0) -> 12 | Q32: =IFERROR(__xludf.DUMMYFUNCTION("""COMPUTED_VALUE"""),0.0) -> 0 | R32: =IFERROR(__xludf.DUMMYFUNCTION("""COMPUTED_VALUE"""),0.0) -> 0 | S32: =IFERROR(__xludf.DUMMYFUNCTION("""COMPUTED_VALUE"""),"Y") -> Y

Sheet invoice
A2: Customer Invoice
A3: Order Date | B3: Cliente Name
A4: =VLOOKUP(A7,Orders!A2:C1000,3,false) -> 46134 | B4: =VLOOKUP(A7,Orders!A2:D1000,4,false)&" "&VLOOKUP(A7,Orders!A2:E1000,5,false) -> Zak Mccormick
A6: Order Number
A7: 1038
A10: Description | B10: Price
A11: =IFERROR(__xludf.DUMMYFUNCTION("FILTER(Orders!F2:F1000, Orders!A2:A1000=A7)"),"Small Desk") -> Small Desk | B11: =IFERROR(__xludf.DUMMYFUNCTION("FILTER(Orders!H2:H1000,Orders!A2:A1000=A7)"),400.0) -> 400
A43: Total: | B43: =SUM(B11:B41) -> 400

Sheet analytics
A2: Tasks by Category | H2: Sales By Product
A4: Category | B4: total | C4: open | D4: Hrs. allotted | E4: Hrs. remaining | F4: % completed
A5: Design | B5: =COUNTIF(Tasks!A$2:A1000,A5) -> 4 | C5: =COUNTIFS(Tasks!A$2:A1000,A5,Tasks!G$2:G1000,"<100") -> 4 | D5: =SUMIFS(Tasks!E$2:E1000,Tasks!A$2:A1000,A5,Tasks!G$2:G1000,"<100") -> 52 | E5: =D5- SUMIFS(Tasks!F$2:F1000,Tasks!A$2:A1000,A5,Tasks!G$2:G1000,"<100") -> 47.5 | F5: =SUMIFS(Tasks!F$2:F1000,Tasks!A$2:A1000,A5,Tasks!G$2:G1000,"<100")/D5 -> 0.086538462
A6: Fabrication | B6: =COUNTIF(Tasks!A$2:A1000,A6) -> 7 | C6: =COUNTIFS(Tasks!A$2:A1000,A6,Tasks!G$2:G1000,"<100") -> 7 | D6: =SUMIFS(Tasks!E$2:E1000,Tasks!A$2:A1000,A6,Tasks!G$2:G1000,"<100") -> 29 | E6: =D6- SUMIFS(Tasks!F$2:F1000,Tasks!A$2:A1000,A6,Tasks!G$2:G1000,"<100") -> 27.5 | F6: =SUMIFS(Tasks!F$2:F1000,Tasks!A$2:A1000,A6,Tasks!G$2:G1000,"<100")/D6 -> 0.051724138
A7: Installation | B7: =COUNTIF(Tasks!A$2:A1000,A7) -> 2 | C7: =COUNTIFS(Tasks!A$2:A1000,A7,Tasks!G$2:G1000,"<100") -> 2 | D7: =SUMIFS(Tasks!E$2:E1000,Tasks!A$2:A1000,A7,Tasks!G$2:G1000,"<100") -> 14 | E7: =D7- SUMIFS(Tasks!F$2:F1000,Tasks!A$2:A1000,A7,Tasks!G$2:G1000,"<100") -> 12.5 | F7: =SUMIFS(Tasks!F$2:F1000,Tasks!A$2:A1000,A7,Tasks!G$2:G1000,"<100")/D7 -> 0.10714286
A8: Materials | B8: =COUNTIF(Tasks!A$2:A1000,A8) -> 4 | C8: =COUNTIFS(Tasks!A$2:A1000,A8,Tasks!G$2:G1000,"<100") -> 4 | D8: =SUMIFS(Tasks!E$2:E1000,Tasks!A$2:A1000,A8,Tasks!G$2:G1000,"<100") -> 6 | E8: =D8- SUMIFS(Tasks!F$2:F1000,Tasks!A$2:A1000,A8,Tasks!G$2:G1000,"<100") -> 5.5 | F8: =SUMIFS(Tasks!F$2:F1000,Tasks!A$2:A1000,A8,Tasks!G$2:G1000,"<100")/D8 -> 0.083333333
A9: Shop maintenance | B9: =COUNTIF(Tasks!A$2:A1000,A9) -> 7 | C9: =COUNTIFS(Tasks!A$2:A1000,A9,Tasks!G$2:G1000,"<100") -> 7 | D9: =SUMIFS(Tasks!E$2:E1000,Tasks!A$2:A1000,A9,Tasks!G$2:G1000,"<100") -> 11 | E9: =D9- SUMIFS(Tasks!F$2:F1000,Tasks!A$2:A1000,A9,Tasks!G$2:G1000,"<100") -> 3 | F9: =SUMIFS(Tasks!F$2:F1000,Tasks!A$2:A1000,A9,Tasks!G$2:G1000,"<100")/D9 -> 0.72727273
J19: Units | K19: Sales
H20: Sales in the last 2 weeks | J20: =COUNTIF(Orders!$C$2:$C1000,">="&today()-14) -> 16 | K20: =SUMIFS(Orders!$H$2:$H1000,Orders!$C$2:$C1000,">="&today()-14) -> 6060
H21: Sales in the previ 2 weeks | J21: =COUNTIF(Orders!$C$2:$C1000,">="&today()-28)-J20 -> 12 | K21: =SUMIFS(Orders!$H$2:$H1000,Orders!$C$2:$C1000,">="&today()-28)-K20 -> 6850
H23: Sales in the last 30 days | J23: =COUNTIF(Orders!$C$2:$C1000,">="&today()-30) -> 30 | K23: =SUMIFS(Orders!$H$2:$H1000,Orders!$C$2:$C1000,">="&today()-30) -> 13310
H24: Sales in the previ 30 days | J24: =COUNTIF(Orders!$C$2:$C1000,">="&today()-60)-J23 -> 23 | K24: =SUMIFS(Orders!$H$2:$H1000,Orders!$C$2:$C1000,">="&today()-60)-K23 -> 9230

Sheet Tasks
A1: Category | B1: Importance | C1: Task | D1: Due Date | E1: Est Total Hours | F1: Hours Spent | G1: % Completed | H1: Big Projet | AA1: Date Helper
A2: Fabrication | B2: Low | C2: Build storage for tools | D2: =today()+AA2 -> 46145 | E2: 2 | F2: 1.5 | G2: 0.75 | H2: =IF( E2>10,"Y","") | AA2: -2
A3: Shop maintenance | B3: Med | C3: Deep clean of dust collector | D3: =today()+AA3 -> 46126 | E3: 2 | F3: 2 | G3: 0.1 | H3: =IF( E3>10,"Y","") | AA3: -21
A4: Design | B4: High | C4: Prepare custom drawings for staircase for Country House project | D4: =today()+AA4 -> 46161 | E4: 16 | F4: 3 | G4: 0.2 | H4: =IF( E4>10,"Y","") -> Y | AA4: 14
A5: Shop maintenance | B5: Med | C5: Replace blades on jointer | D5: =today()+AA5 -> 46132 | E5: 1 | F5: 1 | G5: 0.1 | H5: =IF( E5>10,"Y","") | AA5: -15
A6: Materials | B6: Med | C6: Source walnut for Country House project | D6: =today()+AA6 -> 46145 | E6: 2 | F6: 0.5 | G6: 0.2 | H6: =IF( E6>10,"Y","") | AA6: -2
A7: Fabrication | B7: Med | C7: Glue panels for doors | D7: =today()+AA7 -> 46153 | E7: 6 | F7: 0 | G7: 0 | H7: =IF( E7>10,"Y","") | AA7: 6
A8: Shop maintenance | B8: Med | C8: Deep clean of dust collector | D8: =today()+AA8 -> 46136 | E8: 2 | F8: 2 | G8: 0.1 | H8: =IF( E8>10,"Y","") | AA8: -11
A9: Shop maintenance | B9: Med | C9: Fix tablesaw | D9: =today()+AA9 -> 46140 | E9: 1 | F9: 1 | G9: 0.1 | H9: =IF( E9>10,"Y","") | AA9: -7
A10: Fabrication | B10: Med | C10: Apply finish to custom benches | D10: =today()+AA10 -> 46144 | E10: 2 | F10: 0 | G10: 0 | H10: =IF( E10>10,"Y","") | AA10: -3
A11: Materials | B11: Low | C11: Talk to plywood distributor about discount | D11: =today()+AA11 -> 46148 | E11: 1 | F11: 0 | G11: 0 | H11: =IF( E11>10,"Y","") | AA11: 1
A12: Materials | B12: High | C12: Source marble for tabletop | D12: =today()+AA12 -> 46148 | E12: 2 | F12: 0 | G12: 0 | H12: =IF( E12>10,"Y","") | AA12: 1
A13: Installation | B13: High | C13: Install custom bookshelves in Country House project | D13: =today()+AA13 -> 46151 | E13: 6 | F13: 0.5 | G13: 0.1 | H13: =IF( E13>10,"Y","") | AA13: 4
... A25: Fabrication | B25: High | C25: Apply the finish to the table | D25: =today()+AA25 -> 46156 | E25: 6 | F25: 0 | G25: 0 | H25: =IF( E25>10,"Y","") | AA25: 9

Sheet Orders
A1: Order Number | B1: Status | C1: Order Date | D1: First Name | E1: Last Name | F1: Item | G1: Unit Cost | H1: Sale Price | I1: Paid? | J1: Delivery | K1: Notes | AB1: Date Helper
A2: 1001 | B2: Open | C2: =today()-AB2 -> 46087 | D2: Francesco | E2: Oconnor | F2: Bed Frame | G2: 350 | H2: 800 | I2: Y | J2: Y | AB2: 60
A3: 1002 | B3: Closed | C3: =today()-AB3 -> 46087 | D3: Lyla | E3: Montgomery | F3: End Table | G3: 180 | H3: 400 | I3: Y | AB3: 60
A4: 1003 | B4: Open | C4: =today()-AB4 -> 46088 | D4: Lochlan | E4: Frank | F4: Bed Frame | G4: 350 | H4: 800 | I4: Y | J4: Y | AB4: 59
A5: 1004 | B5: Closed | C5: =today()-AB5 -> 46091 | D5: Adela | E5: Bright | F5: Small Desk | G5: 200 | H5: 400 | I5: Y | AB5: 56
A6: 1005 | B6: Closed | C6: =today()-AB6 -> 46093 | D6: Caine | E6: Hoover | F6: Bench | G6: 100 | H6: 200 | I6: Y | AB6: 54
A7: 1006 | B7: Closed | C7: =today()-AB7 -> 46095 | D7: Jack | E7: Lane | F7: Bookshelf | G7: 240 | H7: 600 | I7: Y | AB7: 52
A8: 1007 | B8: Closed | C8: =today()-AB8 -> 46097 | D8: Olaf | E8: Dunlop | F8: Small Desk | G8: 200 | H8: 400 | I8: Y | AB8: 50
A9: 1008 | B9: Closed | C9: =today()-AB9 -> 46098 | D9: Gillian | E9: Monroe | F9: Coffee table | G9: 120 | H9: 300 | I9: Y | AB9: 49
A10: 1009 | B10: Closed | C10: =today()-AB10 -> 46099 | D10: Talha | E10: Zhang | F10: Small Desk | G10: 200 | H10: 400 | I10: Y | AB10: 48
A11: 1010 | B11: Closed | C11: =today()-AB11 -> 46100 | D11: Logan | E11: Pace | F11: Coffee table | G11: 120 | H11: 300 | I11: Y | AB11: 47
A12: 1011 | B12: Closed | C12: =today()-AB12 -> 46102 | D12: Jaidan | E12: Lord | F12: Wine Rack | G12: 60 | H12: 150 | I12: Y | AB12: 45
A13: 1012 | B13: Closed | C13: =today()-AB13 -> 46103 | D13: Ruari | E13: Hobbs | F13: Coat Rack | G13: 80 | H13: 200 | I13: Y | AB13: 44
A14: 1013 | B14: Closed | C14: =today()-AB14 -> 46104 | D14: Willard | E14: Welsh | F14: Wine Rack | G14: 60 | H14: 150 | I14: Y | AB14: 43
A15: 1014 | B15: Closed | C15: =today()-AB15 -> 46106 | D15: Giorgio | E15: Carver | F15: Bench | G15: 100 | H15: 200 | I15: Y | AB15: 41
A16: 1015 | B16: Closed | C16: =today()-AB16 -> 46106 | D16: Farah | E16: Marsden | F16: Bookshelf | G16: 240 | H16: 600 | I16: Y | AB16: 41
... A20: 1019 | B20: Closed | C20: =today()-AB20 -> 46110 | D20: Shannen | E20: Houghton | F20: Coat Rack | G20: 80 | H20: 200 | I20: Y | AB20: 37
A21: 1020 | B21: Open | C21: =today()-AB21 -> 46113 | D21: Zakir | E21: Roberson | F21: Dining table | G21: 500 | H21: 1200 | I21: Y | J21: Y | AB21: 34
A22: 1021 | B22: Closed | C22: =today()-AB22 -> 46114 | D22: Leslie | E22: Ware | F22: Coffee table | G22: 120 | H22: 300 | I22: Y | AB22: 33
A23: 1022 | B23: Open | C23: =today()-AB23 -> 46114 | D23: Bobbi | E23: Livingston | F23: Large Desk | G23: 300 | H23: 600 | I23: Y | AB23: 33
A24: 1023 | B24: Closed | C24: =today()-AB24 -> 46116 | D24: Daanyaal | E24: Richards | F24: Bookshelf | G24: 240 | H24: 600 | I24: Y | AB24: 31
A25: 1024 | B25: Closed | C25: =today()-AB25 -> 46117 | D25: Stefanie | E25: Sellers | F25: Coat Rack | G25: 80 | H25: 200 | I25: Y | AB25: 30
A26: 1025 | B26: Closed | C26: =today()-AB26 -> 46118 | D26: Bertie | E26: Reed | F26: Bench | G26: 100 | H26: 200 | I26: Y | AB26: 29
A27: 1026 | B27: Closed | C27: =today()-AB27 -> 46119 | D27: Jaxson | E27: Hardy | F27: Small Desk | G27: 200 | H27: 400 | I27: Y | AB27: 28
A28: 1027 | B28: Open | C28: =today()-AB28 -> 46120 | D28: Rayhan | E28: Kennedy | F28: Dining table | G28: 500 | H28: 1200 | I28: Y | J28: Y | AB28: 27
A29: 1028 | B29: Closed | C29: =today()-AB29 -> 46121 | D29: Agatha | E29: Gilmore | F29: Small Desk | G29: 200 | H29: 400 | I29: Y | AB29: 26
A30: 1029 | B30: Open | C30: =today()-AB30 -> 46123 | D30: Larissa | E30: Gough | F30: Dining table | G30: 500 | H30: 1200 | I30: Y | J30: Y | AB30: 24
A31: 1030 | B31: Open | C31: =today()-AB31 -> 46123 | D31: Dalia | E31: Merritt | F31: Large Desk | G31: 300 | H31: 600 | I31: Y | J31: Y | AB31: 24
A32: 1031 | B32: Closed | C32: =today()-AB32 -> 46124 | D32: Joao | E32: Enriquez | F32: Coat Rack | G32: 80 | H32: 200 | I32: Y | AB32: 23
A33: 1032 | B33: Closed | C33: =today()-AB33 -> 46125 | D33: Elaina | E33: Mccoy | F33: Coffee table | G33: 120 | H33: 300 | I33: Y | AB33: 22
A34: 1033 | B34: Closed | C34: =today()-AB34 -> 46126 | D34: Charlotte | E34: Christie | F34: Bookshelf | G34: 240 | H34: 600 | I34: Y | AB34: 21
A35: 1034 | B35: Closed | C35: =today()-AB35 -> 46128 | D35: Abdur | E35: Dean | F35: Wine Rack | G35: 60 | H35: 150 | I35: Y | AB35: 19
A36: 1035 | B36: Open | C36: =today()-AB36 -> 46128 | D36: Saima | E36: Griffin | F36: Large Desk | G36: 300 | H36: 600 | I36: Y | J36: Y | AB36: 19
A37: 1036 | B37: Open | C37: =today()-AB37 -> 46130 | D37: John | E37: Glass | F37: Bookshelf | G37: 240 | H37: 600 | I37: Y | AB37: 17
A38: 1037 | B38: Open | C38: =today()-AB38 -> 46132 | D38: Estelle | E38: Reyna | F38: Bookshelf | G38: 240 | H38: 600 | I38: Y | AB38: 15
A39: 1038 | B39: Open | C39: =today()-AB39 -> 46134 | D39: Zak | E39: Mccormick | F39: Small Desk | G39: 200 | H39: 400 | I39: Y | AB39: 13
A40: 1039 | B40: Closed | C40: =today()-AB40 -> 46135 | D40: Isadora | E40: Massey | F40: Coat Rack | G40: 80 | H40: 200 | I40: Y | AB40: 12
A41: 1040 | B41: Closed | C41: =today()-AB41 -> 46136 | D41: Keri | E41: Burns | F41: Wine Rack | G41: 60 | H41: 150 | I41: Y | AB41: 11
A42: 1041 | B42: Open | C42: =today()-AB42 -> 46138 | D42: Jena | E42: Barker | F42: Dining table | G42: 500 | H42: 1200 | J42: Y | AB42: 9
A43: 1042 | B43: Open | C43: =today()-AB43 -> 46140 | D43: Rhea | E43: Tang | F43: Bench | G43: 100 | H43: 200 | I43: Y | AB43: 7
...
